Workbook

Sheet Sheet1
A1: Артикул | B1: Родительский артикул | C1: Артикул для отображения на сайте | D1: Название модификации (UA) | E1: Название (UA) | F1: Бренд | G1: Раздел | H1: Цена | I1: Старая цена | J1: Валюта | K1: Отображать | L1: Country_of_origin | M1: Наличие | N1: Дополнительные разделы | O1: Фото | P1: Галерея | Q1: Обзор 360 | R1: Алиас | S1: Ссылка | T1: Дата добавления | U1: HTML title (UA) | V1: META keywords (UA) | W1: META description (UA) | X1: h1 заголовок (UA) | Y1: Поставщик | Z1: Иконки | AA1: Скидка % | AB1: Популярность | AC1: Количество | AD1: Описание товара (UA) | AE1: Короткое описание (UA) | AF1: Цвет | AG1: Тип гарантии | AH1: Гарантийный срок, мес. | AI1: Дата и время окончания акции | AJ1: Текст акции (UA) | AK1: Описание для маркетплейсов (UA) | AL1: Выгружать на маркетплейсы | AM1: Состояние товара | AN1: Только для взрослых | AO1: Код УКТ ВЭД | AP1: Срок доставки предзаказа в днях | AQ1: «Оплата частями» ПриватБанка | AR1: «Покупка частями» от monobank | AS1: Код налоговой группы Вчасно.Каса | AT1: Уникальный код налога | AU1: Штрихкод | AV1: Код производителя товара (MPN) | AW1: На складе для Prom | AX1: Электронный товар | AY1: Аксессуары(товары)
A2: 2009140 | B2: 2009140 | C2: 2009140 | D2: Щітка силіконова для тварин Fiskars , 2/6, 19L (2009140) | E2: Щітка силіконова для тварин Fiskars , 2/6, 19L (2009140) | F2: Fiskars | G2: FISKARS/ Аксесуари для тварин | H2: 1199.00 | I2: 0.00 | J2: UAH | K2: Да | L2: =VLOOKUP(C2,Sheet1!$C:$L,10,0) -> China | M2: Немає в наявності | O2: https://fiskars-gratis.com.ua/content/images/3/shchitka-sylikonova-dlia-tvaryn-fiskars-2-6-19l-1816520-19949308723507_+ef08531431.jpg; https://fiskars-gratis.com.ua/content/images/3/shchitka-sylikonova-dlia-tvaryn-fiskars-2-6-19l-1816520-14896186801593_+11eb0c30f6.jpg; https://fiskars-gratis.com.ua/content/images/3/shchitka-sylikonova-dlia-tvaryn-fiskars-2-6-19l-1816520-41587634878457_+dbfc746b32.jpg | R2: shchitka-sylikonova-dlia-tvaryn-fiskars-2-6-19l-1816520 | S2: https://fiskars-gratis.com.ua/shchitka-sylikonova-dlia-tvaryn-fiskars-2-6-19l-1816520/ | T2: 2026-03-15 23:17:10 | X2: Щітка силіконова для тварин Fiskars , 2/6, 19L | AA2: 0 | AB2: 0 | AC2: 0 | AD2: <p data-end="320" data-start="0"><span style="font-size:18px;"><strong data-end="49" data-start="0">Щітка силіконова для тварин Fiskars (2009140)</strong> </span><span style="font-size:14px;">&mdash; ручний інструмент для догляду за шерстю домашніх тварин, призначений для очищення шерсті, збирання випалого волосся та м&rsquo;якого масажу шкіри під час щоденного грумінгу. Використовується для догляду за собаками, котами та іншими домашніми тваринами у побутових умовах.</span></p> <p data-end="547" data-start="322"><span style="font-size:18px;"><strong data-end="338" data-start="322">Призначення:</strong> </span><span style="font-size:14px;">підходить для регулярного очищення шерсті від пилу, бруду та відмерлого волосся. Може застосовуватися під час сухого чищення або під час миття тварини для рівномірного розподілу води та засобів для догляду.</span></p> <p data-end="816" data-start="549"><span style="font-size:18px;"><strong data-end="565" data-start="549">Конструкція:</strong> </span><span style="font-size:14px;">робоча поверхня оснащена гнучкими силіконовими зубцями, які м&rsquo;яко контактують зі шкірою тварини та допомагають відокремлювати випалу шерсть без надмірного натискання. Форма інструмента дозволяє контролювати рухи під час обробки різних ділянок тіла.</span></p> <p data-end="991" data-start="818"><span style="font-size:18px;"><strong data-end="832" data-start="818">Матеріали:</strong> </span><span style="font-size:14px;">робоча частина виготовлена з еластичного силікону, стійкого до вологи та регулярного очищення. Корпус адаптований для ручного використання під час грумінгу.</span></p> <p data-end="1154" data-is-last-node="" data-is-only-node="" data-start="993"><span style="font-size:18px;"><strong data-end="1009" data-start="993">Особливості:</strong> </span><span style="font-size:14px;">інструмент призначений для систематичного догляду за домашніми тваринами та використовується як частина базового набору аксесуарів для грумінгу.</span></p> | AE2: Щітка силіконова для тварин Fiskars — ручний інструмент для догляду за шерстю домашніх тварин, призначений для очищення шерсті, збирання випалого волосся та м’якого масажу шкіри під час щоденного грумінгу. Використовується для догляду за собаками, котами та іншими домашніми тваринами у побутових умовах. | AH2: 0 | AI2: 2026-03-15 23:16:04 | AN2: Нет | AO2: 9603909100 | AP2: 0 | AQ2: Выкл | AR2: Выкл | AU2: 0046561816520 | AW2: Нет | AX2: Нет
A3: 2009136 | B3: 2009136 | C3: 2009136 | D3: Засіб для розплутування/розплутувач для тварин Fiskars, 2/6, 19L (2009136) | E3: Засіб для розплутування/розплутувач для тварин Fiskars, 2/6, 19L (2009136) | F3: Fiskars | G3: FISKARS/ Аксесуари для тварин | H3: 1199.00 | I3: 0.00 | J3: UAH | K3: Да | L3: =VLOOKUP(C3,Sheet1!$C:$L,10,0) -> China | M3: Немає в наявності | O3: https://fiskars-gratis.com.ua/content/images/4/zasib-dlia-rozplutuvannia-rozplutuvach-dlia-tvaryn-fiskars-2-6-19l-1816506-29339940044536_+86d4a5677e.jpg; https://fiskars-gratis.com.ua/content/images/4/zasib-dlia-rozplutuvannia-rozplutuvach-dlia-tvaryn-fiskars-2-6-19l-1816506-34032061364411_+dd836bc0c0.jpg | R3: zasib-dlia-rozplutuvannia-rozplutuvach-dlia-tvaryn-fiskars-2-6-19l-1816506 | S3: https://fiskars-gratis.com.ua/zasib-dlia-rozplutuvannia-rozplutuvach-dlia-tvaryn-fiskars-2-6-19l-1816506/ | T3: 2026-03-15 23:27:42 | X3: Засіб для розплутування/розплутувач для тварин Fiskars, 2/6, 19L | AA3: 0 | AB3: 0 | AC3: 0 | AD3: <p data-end="280" data-start="0"><span style="font-size:18px;"><strong data-end="59" data-start="0">Засіб для розплутування шерсті тварин Fiskars (2009136)</strong> </span><span style="font-size:14px;">&mdash; ручний інструмент для догляду за шерстю домашніх тварин, призначений для розплутування ковтунів і розділення зваляної шерсті. Використовується під час регулярного грумінгу собак і котів із середньою та довгою шерстю.</span></p> <p data-end="525" data-start="282"><span style="font-size:18px;"><strong data-end="298" data-start="282">Призначення:</strong></span><span style="font-size:14px;"> підходить для усунення ковтунів, розділення злиплих пасом шерсті та підготовки шерсті до подальшого вичісування. Застосовується під час догляду за домашніми тваринами у побутових умовах або під час базових процедур грумінгу.</span></p> <p data-end="777" data-start="527"><span style="font-size:18px;"><strong data-end="543" data-start="527">Конструкція:</strong></span><span style="font-size:14px;"> робоча частина оснащена кількома зубцями, розташованими таким чином, щоб поступово розділяти зваляну шерсть і зменшувати натяг під час розплутування. Форма інструмента дозволяє обробляти ділянки з густою шерстю та локальні ковтуни.</span></p> <p data-end="930" data-start="779"><span style="font-size:18px;"><strong data-end="793" data-start="779">Матеріали:</strong></span><span style="font-size:14px;"> зубці виготовлені зі сталі, розрахованої на регулярний контакт із щільною шерстю. Руків&rsquo;я адаптоване для контрольованої ручної роботи.</span></p> <p data-end="1080" data-is-last-node="" data-is-only-node="" data-start="932"><span style="font-size:18px;"><strong data-end="948" data-start="932">Особливості:</strong> </span><span style="font-size:14px;">інструмент призначений для систематичного догляду за шерстю домашніх тварин і використовується як частина базового набору грумінгу.</span></p> | AE3: Засіб для розплутування шерсті тварин Fiskars — ручний інструмент для догляду за шерстю домашніх тварин, призначений для розплутування ковтунів і розділення зваляної шерсті. Використовується під час регулярного грумінгу собак і котів із середньою та довгою шерстю. | AH3: 0 | AI3: 2026-03-15 23:27:09 | AN3: Нет | AO3: 9615190000 | AP3: 0 | AQ3: Выкл | AR3: Выкл | AU3: 0046561816506 | AW3: Нет | AX3: Нет
A4: 2009138 | B4: 2009138 | C4: 2009138 | D4: Щітка дротяна для тварин Fiskars, 2/6, 19L (2009138) | E4: Щітка дротяна для тварин Fiskars, 2/6, 19L (2009138) | F4: Fiskars | G4: FISKARS/ Аксесуари для тварин | H4: 1199.00 | I4: 0.00 | J4: UAH | K4: Да | L4: =VLOOKUP(C4,Sheet1!$C:$L,10,0) -> China | M4: Немає в наявності | O4: https://fiskars-gratis.com.ua/content/images/6/shchitka-drotiana-dlia-tvaryn-fiskars-2-6-19l-1816513-52365508642650_+475fdecdea.jpg; https://fiskars-gratis.com.ua/content/images/6/shchitka-drotiana-dlia-tvaryn-fiskars-2-6-19l-1816513-15244716117334_+0ff4db14f1.jpg | R4: shchitka-drotiana-dlia-tvaryn-fiskars-2-6-19l-1816513 | S4: https://fiskars-gratis.com.ua/shchitka-drotiana-dlia-tvaryn-fiskars-2-6-19l-1816513/ | T4: 2026-03-15 23:30:06 | X4: Щітка дротяна для тварин Fiskars, 2/6, 19L | AA4: 0 | AB4: 0 | AC4: 0 | AD4: <p data-end="306" data-start="0"><span style="font-size:18px;"><strong data-end="46" data-start="0">Щітка дротяна для тварин Fiskars (2009138)</strong> </span><span style="font-size:14px;">&mdash; ручний інструмент для догляду за шерстю домашніх тварин, призначений для вичісування підшерстка та видалення випалої шерсті під час регулярного грумінгу. Використовується для очищення шерсті собак і котів від пилу, дрібних забруднень і відмерлого волосся.</span></p> <p data-end="492" data-start="308"><span style="font-size:18px;"><strong data-end="324" data-start="308">Призначення:</strong></span><span style="font-size:14px;"> підходить для догляду за шерстю середньої та довгої довжини, видалення підшерстка під час линяння, а також для підтримання охайного стану шерстяного покриву тварини.</span></p> <p data-end="744" data-start="494"><span style="font-size:18px;"><strong data-end="510" data-start="494">Конструкція:</strong></span><span style="font-size:14px;"> робоча поверхня оснащена тонкими дротяними зубцями, розташованими на гнучкій основі. Така конструкція дозволяє проникати у верхні шари шерсті, відокремлювати випалу шерсть і рівномірно розподіляти навантаження під час розчісування.</span></p> <p data-end="938" data-start="746"><span style="font-size:18px;"><strong data-end="760" data-start="746">Матеріали:</strong> </span><span style="font-size:14px;">зубці виготовлені з металевого дроту, розрахованого на регулярний контакт із шерстю. Основа та руків&rsquo;я адаптовані для контрольованої ручної роботи під час догляду за твариною.</span></p> <p data-end="1106" data-is-last-node="" data-is-only-node="" data-start="940"><span style="font-size:18px;"><strong data-end="956" data-start="940">Особливості:</strong> </span><span style="font-size:14px;">інструмент призначений для систематичного грумінгу домашніх тварин і використовується для підтримання чистоти та структури шерсті у побутових умовах.</span></p> | AE4: Щітка дротяна для тварин Fiskars — ручний інструмент для догляду за шерстю домашніх тварин, призначений для вичісування підшерстка та видалення випалої шерсті під час регулярного грумінгу. Використовується для очищення шерсті собак і котів від пилу, дрібних забруднень і відмерлого волосся. | AH4: 0 | AI4: 2026-03-15 23:29:03 | AN4: Нет | AO4: 9603909100 | AP4: 0 | AQ4: Выкл | AR4: Выкл | AU4: 0046561816513 | AW4: Нет | AX4: Нет
A5: 2009144 | B5: 2009144 | C5: 2009144 | D5: Сумка для зберігання інструментів для грумінгу FISKARS, 2/6, 19L (2009144) | E5: Сумка для зберігання інструментів для грумінгу FISKARS, 2/6, 19L (2009144) | F5: Fiskars | G5: FISKARS/ Аксесуари для тварин | H5: 1199.00 | I5: 0.00 | J5: UAH | K5: Да | L5: =VLOOKUP(C5,Sheet1!$C:$L,10,0) -> China | M5: Немає в наявності | O5: https://fiskars-gratis.com.ua/content/images/7/sumka-dlia-zberihannia-instrumentiv-dlia-hruminhu-fiskars-2-6-19l-1816544-55397096399844_+7974f3c32c.jpg; https://fiskars-gratis.com.ua/content/images/7/sumka-dlia-zberihannia-instrumentiv-dlia-hruminhu-fiskars-2-6-19l-1816544-47667126360409_+2662186932.jpg | R5: sumka-dlia-zberihannia-instrumentiv-dlia-hruminhu-fiskars-2-6-19l-1816544 | S5: https://fiskars-gratis.com.ua/sumka-dlia-zberihannia-instrumentiv-dlia-hruminhu-fiskars-2-6-19l-1816544/ | T5: 2026-03-15 23:30:29 | X5: Сумка для зберігання інструментів для грумінгу FISKARS, 2/6, 19L | AA5: 0 | AB5: 0 | AC5: 0 | AD5: <p data-end="311" data-start="0"><span style="font-size:18px;"><strong data-end="68" data-start="0">Сумка для зберігання інструментів для грумінгу Fiskars (2009144)</strong> </span><span style="font-size:14px;">&mdash; допоміжний аксесуар для організації та транспортування інструментів догляду за домашніми тваринами. Використовується для зберігання щіток, гребінців, розплутувачів шерсті та інших предметів, що застосовуються під час регулярного грумінгу.</span></p> <p data-end="582" data-start="313"><span style="font-size:18px;"><strong data-end="329" data-start="313">Призначення:</strong></span><span style="font-size:14px;"> підходить для систематичного зберігання інструментів догляду за шерстю собак і котів, упорядкування аксесуарів для грумінгу та їх переміщення між місцями використання. Може застосовуватися у побутових умовах або під час виїзного догляду за тваринами.</span></p> <p data-end="795" data-start="584"><span style="font-size:18px;"><strong data-end="600" data-start="584">Конструкція:</strong></span><span style="font-size:14px;"> сумка має містке основне відділення та внутрішній простір, адаптований для розміщення інструментів різного формату. Форма виробу дозволяє зручно складати та діставати аксесуари під час роботи.</span></p> <p data-end="977" data-start="797"><span style="font-size:18px;"><strong data-end="811" data-start="797">Матеріали:</strong></span><span style="font-size:14px;"> корпус виготовлений із зносостійкого текстильного матеріалу, розрахованого на регулярне використання. Ручки забезпечують зручне перенесення сумки разом із вмістом.</span></p> <p data-end="1180" data-is-last-node="" data-is-only-node="" data-start="979"><span style="font-size:18px;"><strong data-end="995" data-start="979">Особливості:</strong></span><span style="font-size:14px;"> об&rsquo;єм сумки становить приблизно 19 л. Аксесуар призначений для організованого зберігання інструментів грумінгу та використовується як частина набору для догляду за домашніми тваринами.</span></p> | AE5: Сумка для зберігання інструментів для грумінгу Fiskars — допоміжний аксесуар для організації та транспортування інструментів догляду за домашніми тваринами. Використовується для зберігання щіток, гребінців, розплутувачів шерсті та інших предметів, що застосовуються під час регулярного грумінгу. | AH5: 0 | AI5: 2026-03-15 23:30:09 | AN5: Нет | AO5: 4202229090 | AP5: 0 | AQ5: Выкл | AR5: Выкл | AU5: 0046561816544 | AW5: Нет | AX5: Нет
A6: 2009124 | B6: 2009124 | C6: 2009124 | D6: Ножиці для тварин з закругленими кінцями Fiskars, 2/6, 19L (2009124) | E6: Ножиці для тварин з закругленими кінцями Fiskars, 2/6, 19L (2009124) | F6: Fiskars | G6: FISKARS/ Аксесуари для тварин | H6: 1199.00 | I6: 0.00 | J6: UAH | K6: Да | L6: =VLOOKUP(C6,Sheet1!$C:$L,10,0) -> China | M6: Немає в наявності | O6: https://fiskars-gratis.com.ua/content/images/11/nozhytsi-dlia-tvaryn-z-zakruhlenymy-kintsiamy-fiskars-2-6-19l-1816445-83110909485205_+9d0ed96364.jpg; https://fiskars-gratis.com.ua/content/images/11/nozhytsi-dlia-tvaryn-z-zakruhlenymy-kintsiamy-fiskars-2-6-19l-1816445-87437518294057_+56b0e0016b.jpg | R6: nozhytsi-dlia-tvaryn-z-zakruhlenymy-kintsiamy-fiskars-2-6-19l-1816445 | S6: https://fiskars-gratis.com.ua/nozhytsi-dlia-tvaryn-z-zakruhlenymy-kintsiamy-fiskars-2-6-19l-1816445/ | T6: 2026-03-15 23:32:07 | X6: Ножиці для тварин з закругленими кінцями Fiskars, 2/6, 19L | AA6: 0 | AB6: 0 | AC6: 0 | AD6: <article data-scroll-anchor="true" data-testid="conversation-turn-24" data-turn="assistant" data-turn-id="request-69b34cbf-a33c-8331-8c2a-2d7e0ab1d4ae-8" dir="auto" tabindex="-1"> <p data-end="322" data-start="0"><span style="font-size:18px;"><strong data-end="63" data-start="0">Ножиці для тварин із закругленими кінцями Fiskars (2009124)</strong> </span><span style="font-size:14px;">&mdash; ручний інструмент для догляду за шерстю домашніх тварин, призначений для підстригання та корекції шерсті під час базових процедур грумінгу. Використовуються для акуратної обробки окремих ділянок шерстяного покриву у собак, котів та інших домашніх тварин.</span></p> <p data-end="537" data-start="324"><span style="font-size:18px;"><strong data-end="340" data-start="324">Призначення:</strong></span><span style="font-size:14px;"> підходять для підрівнювання шерсті, видалення зайвих пасом та обробки делікатних зон, зокрема навколо лап, морди або вух. Застосовуються під час регулярного догляду за шерстю у побутових умовах.</span></p> <p data-end="770" data-start="539"><span style="font-size:18px;"><strong data-end="555" data-start="539">Конструкція:</strong></span><span style="font-size:14px;"> ножиці оснащені лезами із закругленими кінцями, що зменшує ризик випадкового травмування шкіри під час роботи. Форма інструмента дозволяє виконувати точне підстригання та контролювати рухи під час обробки шерсті.</span></p> <p data-end="937" data-start="772"><span style="font-size:18px;"><strong data-end="786" data-start="772">Матеріали:</strong></span><span style="font-size:14px;"> леза виготовлені зі сталі, стійкої до регулярного використання. Руків&rsquo;я адаптовані для стабільного утримання інструмента та контрольованого різання.</span></p> <p data-end="1102" data-is-last-node="" data-is-only-node="" data-start="939"><span style="font-size:18px;"><strong data-end="955" data-start="939">Особливості:</strong></span><span style="font-size:14px;"> інструмент призначений для систематичного догляду за шерстю домашніх тварин і використовується як частина базового набору аксесуарів для грумінгу.</span></p> </article> | AE6: Ножиці для тварин із закругленими кінцями Fiskars — ручний інструмент для догляду за шерстю домашніх тварин, призначений для підстригання та корекції шерсті під час базових процедур грумінгу. Використовуються для акуратної обробки окремих ділянок шерстяного покриву у собак, котів та інших домашніх тварин. | AH6: 0 | AI6: 2026-03-15 23:31:47 | AN6: Нет | AO6: 8213000000 | AP6: 0 | AQ6: Выкл | AR6: Выкл | AU6: 0046561816445 | AW6: Нет | AX6: Нет
A7: 2009126 | B7: 2009126 | C7: 2009126 | D7: Ножиці прямі для тварин Fiskars, 2/6, 19L (2009126) | E7: Ножиці прямі для тварин Fiskars, 2/6, 19L (2009126) | F7: Fiskars | G7: FISKARS/ Аксесуари для тварин | H7: 1499.00 | I7: 0.00 | J7: UAH | K7: Да | L7: =VLOOKUP(C7,Sheet1!$C:$L,10,0) -> China | M7: Немає в наявності | O7: https://fiskars-gratis.com.ua/content/images/12/nozhytsi-priami-dlia-tvaryn-fiskars-2-6-19l-1816452-71856194063740_+b99da2d1ee.jpg; https://fiskars-gratis.com.ua/content/images/12/nozhytsi-priami-dlia-tvaryn-fiskars-2-6-19l-1816452-81481929345795_+48d5b18bc4.jpg | R7: nozhytsi-priami-dlia-tvaryn-fiskars-2-6-19l-1816452 | S7: https://fiskars-gratis.com.ua/nozhytsi-priami-dlia-tvaryn-fiskars-2-6-19l-1816452/ | T7: 2026-03-15 23:32:33 | X7: Ножиці прямі для тварин Fiskars, 2/6, 19L | AA7: 0 | AB7: 0 | AC7: 0 | AD7: <p data-end="290" data-start="0"><span style="font-size:18px;"><strong data-end="45" data-start="0">Ножиці прямі для тварин Fiskars (2009126)</strong></span><span style="font-size:14px;"> &mdash; ручний інструмент для догляду за шерстю домашніх тварин, призначений для підстригання та вирівнювання шерстяного покриву під час процедур грумінгу. Використовуються для обробки окремих ділянок шерсті у собак, котів та інших домашніх тварин.</span></p> <p data-end="500" data-start="292"><span style="font-size:18px;"><strong data-end="308" data-start="292">Призначення:</strong></span><span style="font-size:14px;"> підходять для підрівнювання шерсті, видалення зайвих пасом і корекції форми шерстяного покриву. Можуть застосовуватися під час регулярного догляду за шерстю на різних ділянках тіла тварини.</span></p> <p data-end="712" data-start="502"><span style="font-size:18px;"><strong data-end="518" data-start="502">Конструкція:</strong></span><span style="font-size:14px;"> інструмент оснащений прямими ріжучими лезами, що дозволяє виконувати рівні та контрольовані зрізи шерсті. Форма ножиць забезпечує точність під час роботи та зручність обробки окремих ділянок.</span></p> <p data-end="904" data-start="714"><span style="font-size:18px;"><strong data-end="728" data-start="714">Матеріали:</strong></span><span style="font-size:14px;"> леза виготовлені зі сталі, стійкої до регулярного використання під час підстригання шерсті. Руків&rsquo;я адаптовані для стабільного утримання інструмента та контрольованих рухів.</span></p> <p data-end="1069" data-is-last-node="" data-is-only-node="" data-start="906"><span style="font-size:18px;"><strong data-end="922" data-start="906">Особливості:</strong></span><span style="font-size:14px;"> інструмент призначений для систематичного догляду за шерстю домашніх тварин і використовується як частина базового набору аксесуарів для грумінгу.</span></p> | AE7: Ножиці прямі для тварин Fiskars — ручний інструмент для догляду за шерстю домашніх тварин, призначений для підстригання та вирівнювання шерстяного покриву під час процедур грумінгу. Використовуються для обробки окремих ділянок шерсті у собак, котів та інших домашніх тварин. | AH7: 0 | AI7: 2026-03-15 23:32:10 | AN7: Нет | AO7: 8213000000 | AP7: 0 | AQ7: Выкл | AR7: Выкл | AU7: 0046561816452 | AW7: Нет | AX7: Нет
A8: 2009128 | B8: 2009128 | C8: 2009128 | D8: Ножиці філірувальні (блендінг) для тварин (Fiskars), 2/6, 19L (2009128) | E8: Ножиці філірувальні (блендінг) для тварин (Fiskars), 2/6, 19L (2009128) | F8: Fiskars | G8: FISKARS/ Аксесуари для тварин | H8: 1499.00 | I8: 0.00 | J8: UAH | K8: Да | L8: =VLOOKUP(C8,Sheet1!$C:$L,10,0) -> China | M8: Немає в наявності | O8: https://fiskars-gratis.com.ua/content/images/13/nozhytsi-filiruvalni-blendinh-dlia-tvaryn-fiskars-2-6-19l-1816469-78361708951723_+5249067c85.jpg; https://fiskars-gratis.com.ua/content/images/13/nozhytsi-filiruvalni-blendinh-dlia-tvaryn-fiskars-2-6-19l-1816469-34108446666732_+04c64bf6b4.jpg | R8: nozhytsi-filiruvalni-blendinh-dlia-tvaryn-fiskars-2-6-19l-1816469 | S8: https://fiskars-gratis.com.ua/nozhytsi-filiruvalni-blendinh-dlia-tvaryn-fiskars-2-6-19l-1816469/ | T8: 2026-03-15 23:32:57 | X8: Ножиці філірувальні (блендінг) для тварин (Fiskars), 2/6, 19L | AA8: 0 | AB8: 0 | AC8: 0 | AD8: <p data-end="332" data-start="0"><span style="font-size:18px;"><strong data-end="63" data-start="0">Ножиці філірувальні (блендінг) для тварин Fiskars (2009128)</strong> </span><span style="font-size:14px;">&mdash; ручний інструмент для догляду за шерстю домашніх тварин, призначений для проріджування та плавного вирівнювання шерстяного покриву під час процедур грумінгу. Використовуються для обробки шерсті у собак, котів та інших домашніх тварин із середньою та довгою шерстю.</span></p> <p data-end="583" data-start="334"><span style="font-size:18px;"><strong data-end="350" data-start="334">Призначення:</strong></span><span style="font-size:14px;"> підходять для зменшення густоти шерсті, пом&rsquo;якшення ліній після підстригання та формування природного переходу між ділянками різної довжини. Застосовуються під час корекції форми шерстяного покриву та завершального етапу грумінгу.</span></p> <p data-end="803" data-start="585"><span style="font-size:18px;"><strong data-end="601" data-start="585">Конструкція:</strong></span><span style="font-size:14px;"> один із ріжучих елементів має зубчасту кромку, що дозволяє частково зрізати пасма шерсті під час кожного руху. Така конструкція забезпечує поступове проріджування та контрольований результат обробки.</span></p> <p data-end="1006" data-start="805"><span style="font-size:18px;"><strong data-end="819" data-start="805">Матеріали:</strong></span><span style="font-size:14px;"> леза виготовлені зі сталі, стійкої до регулярного використання під час підстригання шерсті. Руків&rsquo;я адаптовані для стабільного утримання інструмента та точного контролю під час роботи.</span></p> <p data-end="1173" data-is-last-node="" data-is-only-node="" data-start="1008"><span style="font-size:18px;"><strong data-end="1024" data-start="1008">Особливості:</strong> </span><span style="font-size:14px;">інструмент призначений для систематичного догляду за шерстю домашніх тварин і використовується як частина базового набору інструментів для грумінгу.</span></p> | AE8: Ножиці філірувальні (блендінг) для тварин Fiskars — ручний інструмент для догляду за шерстю домашніх тварин, призначений для проріджування та плавного вирівнювання шерстяного покриву під час процедур грумінгу. Використовуються для обробки шерсті у собак, котів та інших домашніх тварин із середньою та довгою шерстю. | AH8: 0 | AI8: 2026-03-15 23:32:41 | AN8: Нет | AO8: 8213000000 | AP8: 0 | AQ8: Выкл | AR8: Выкл | AU8: 0046561816469 | AW8: Нет | AX8: Нет
A9: 2009142 | B9: 2009142 | C9: 2009142 | D9: Пилка для нігтів для тварин Fiskars, 2/6, 19L (2009142) | E9: Пилка для нігтів для тварин Fiskars, 2/6, 19L (2009142) | F9: Fiskars | G9: FISKARS/ Аксесуари для тварин | H9: 779.00 | I9: 0.00 | J9: UAH | K9: Да | L9: =VLOOKUP(C9,Sheet1!$C:$L,10,0) -> China | M9: Немає в наявності | O9: https://fiskars-gratis.com.ua/content/images/10/pylka-dlia-nihtiv-dlia-tvaryn-fiskars-2-6-19l-1816537-56320074752080_+f28095bc32.jpg; https://fiskars-gratis.com.ua/content/images/10/pylka-dlia-nihtiv-dlia-tvaryn-fiskars-2-6-19l-1816537-92642854358221_+32aec2c9ea.jpg | P9: https://fiskars-gratis.com.ua/content/images/10/pylka-dlia-nihtiv-dlia-tvaryn-fiskars-2-6-19l-1816537-60009927375491_+40112f27b8.jpg; https://fiskars-gratis.com.ua/content/images/10/pylka-dlia-nihtiv-dlia-tvaryn-fiskars-2-6-19l-1816537-44574560488484_+a3fdfeca40.jpg | R9: pylka-dlia-nihtiv-dlia-tvaryn-fiskars-2-6-19l-1816537 | S9: https://fiskars-gratis.com.ua/pylka-dlia-nihtiv-dlia-tvaryn-fiskars-2-6-19l-1816537/ | T9: 2026-03-15 23:31:42 | X9: Пилка для нігтів для тварин Fiskars, 2/6, 19L | AA9: 0 | AB9: 0 | AC9: 0 | AD9: <p data-end="283" data-start="0"><span style="font-size:18px;"><strong data-end="49" data-start="0">Пилка для нігтів для тварин Fiskars (2009142)</strong> </span><span style="font-size:14px;">&mdash; ручний інструмент для догляду за кігтями домашніх тварин, призначений для підпилювання та згладжування країв кігтів після підстригання. Використовується під час регулярного догляду за лапами собак, котів та інших домашніх тварин.</span></p> <p data-end="504" data-start="285"><span style="font-size:18px;"><strong data-end="301" data-start="285">Призначення:</strong> </span><span style="font-size:14px;">підходить для корекції форми кігтів, усунення гострих країв після обрізання та підтримання їх безпечної довжини. Може застосовуватися як завершальний етап догляду за кігтями під час процедур грумінгу.</span></p> <p data-end="722" data-start="506"><span style="font-size:18px;"><strong data-end="522" data-start="506">Конструкція:</strong></span><span style="font-size:14px;"> інструмент має подовжену робочу поверхню з абразивним покриттям, що дозволяє поступово знімати верхній шар кігтя та вирівнювати його край. Форма пилки забезпечує контрольовані рухи під час обробки.</span></p> <p data-end="915" data-start="724"><span style="font-size:18px;"><strong data-end="738" data-start="724">Матеріали:</strong></span><span style="font-size:14px;"> робоча частина виготовлена з матеріалу з абразивним покриттям, стійким до регулярного використання. Руків&rsquo;я адаптоване для ручної роботи та стабільного утримання інструмента.</span></p> <p data-end="1081" data-is-last-node="" data-is-only-node="" data-start="917"><span style="font-size:18px;"><strong data-end="933" data-start="917">Особливості:</strong></span><span style="font-size:14px;"> інструмент призначений для систематичного догляду за кігтями домашніх тварин і використовується як частина базового набору аксесуарів для грумінгу.</span></p> | AE9: Пилка для нігтів для тварин Fiskars — ручний інструмент для догляду за кігтями домашніх тварин, призначений для підпилювання та згладжування країв кігтів після підстригання. Використовується під час регулярного догляду за лапами собак, котів та інших домашніх тварин. | AH9: 0 | AI9: 2026-03-15 23:31:27 | AN9: Нет | AO9: 8214200000 | AP9: 0 | AQ9: Выкл | AR9: Выкл | AU9: 0046561816537 | AW9: Нет | AX9: Нет
A10: 2009134 | B10: 2009134 | C10: 2009134 | D10: Гребінець сталевий для тварин Fiskars , 2/6, 19L (2009134) | E10: Гребінець сталевий для тварин Fiskars , 2/6, 19L (2009134) | F10: Fiskars | G10: FISKARS/ Аксесуари для тварин | H10: 899.00 | I10: 0.00 | J10: UAH | K10: Да | L10: =VLOOKUP(C10,Sheet1!$C:$L,10,0) -> China | M10: Немає в наявності | O10: https://fiskars-gratis.com.ua/content/images/5/hrebinets-stalevyi-dlia-tvaryn-fiskars-2-6-19l-1816490-25490070556696_+0b2f5fff30.jpg; https://fiskars-gratis.com.ua/content/images/5/hrebinets-stalevyi-dlia-tvaryn-fiskars-2-6-19l-1816490-11869273543600_+251a60aef9.jpg | R10: hrebinets-stalevyi-dlia-tvaryn-fiskars-2-6-19l-1816490 | S10: https://fiskars-gratis.com.ua/hrebinets-stalevyi-dlia-tvaryn-fiskars-2-6-19l-1816490/ | T10: 2026-03-15 23:28:53 | X10: Гребінець сталевий для тварин Fiskars , 2/6, 19L | AA10: 0 | AB10: 0 | AC10: 0 | AD10: <p data-end="303" data-start="0"><span style="font-size:18px;"><strong data-end="51" data-start="0">Гребінець сталевий для тварин Fiskars 2009134)</strong> </span><span style="font-size:14px;">&mdash; ручний інструмент для догляду за шерстю домашніх тварин, призначений для розчісування, видалення випалої шерсті та підтримання охайного стану шерстяного покриву. Використовується під час регулярного грумінгу собак і котів із різними типами шерсті.</span></p> <p data-end="557" data-start="305"><span style="font-size:18px;"><strong data-end="321" data-start="305">Призначення:</strong></span><span style="font-size:14px;"> підходить для щоденного розчісування, розділення пасом шерсті, видалення пилу та випалого підшерстка. Може застосовуватися для догляду за шерстю на різних ділянках тіла тварини та для підготовки шерсті до подальших процедур грумінгу.</span></p> <p data-end="787" data-start="559"><span style="font-size:18px;"><strong data-end="575" data-start="559">Конструкція:</strong></span><span style="font-size:14px;"> робоча частина оснащена рядом металевих зубців, розташованих на оптимальній відстані для рівномірного проходження крізь шерсть. Така форма дозволяє акуратно розділяти шерсть і контролювати процес розчісування.</span></p> <p data-end="981" data-start="789"><span style="font-size:18px;"><strong data-end="803" data-start="789">Матеріали:</strong></span><span style="font-size:14px;"> зубці виготовлені зі сталі, стійкої до регулярного використання та контакту з шерстю. Руків&rsquo;я адаптоване для ручної роботи та стабільного контролю під час догляду за твариною.</span></p> <p data-end="1116" data-is-last-node="" data-is-only-node="" data-start="983"><span style="font-size:18px;"><strong data-end="999" data-start="983">Особливості:</strong></span><span style="font-size:14px;"> інструмент призначений для систематичного використання під час базового грумінгу домашніх тварин у побутових умовах.</span></p> | AH10: 0 | AI10: 2026-03-15 23:28:30 | AN10: Нет | AO10: 9615190000 | AP10: 0 | AQ10: Выкл | AR10: Выкл | AU10: 0046561816490 | AW10: Нет | AX10: Нет
A11: 2009130 | B11: 2009130 | C11: 2009130 | D11: Кусачки для кігтів тварин Fiskars, 2/6, 19L (2009130) | E11: Кусачки для кігтів тварин Fiskars, 2/6, 19L (2009130) | F11: Fiskars | G11: FISKARS/ Аксесуари для тварин | H11: 899.00 | I11: 0.00 | J11: UAH | K11: Да | L11: =VLOOKUP(C11,Sheet1!$C:$L,10,0) -> China | M11: Немає в наявності | O11: https://fiskars-gratis.com.ua/content/images/9/kusachky-dlia-kihtiv-tvaryn-fiskars-2-6-19l-1816476-86760677284993_+4c79a29113.jpg; https://fiskars-gratis.com.ua/content/images/9/kusachky-dlia-kihtiv-tvaryn-fiskars-2-6-19l-1816476-98965090991984_+e21c68fefc.jpg | R11: kusachky-dlia-kihtiv-tvaryn-fiskars-2-6-19l-1816476 | S11: https://fiskars-gratis.com.ua/kusachky-dlia-kihtiv-tvaryn-fiskars-2-6-19l-1816476/ | T11: 2026-03-15 23:31:16 | X11: Кусачки для кігтів тварин Fiskars, 2/6, 19L | AA11: 0 | AB11: 0 | AC11: 0 | AD11: <article data-scroll-anchor="false" data-testid="conversation-turn-19" data-turn="user" data-turn-id="4a6859b5-372f-4ff1-9c57-2b6de5d35b36" dir="auto" tabindex="-1"><span style="font-size: 18px;"><strong data-end="47" data-start="0">Кусачки для кігтів тварин Fiskars (2009130)</strong> </span><span style="font-size: 14px;">&mdash; ручний інструмент для підстригання кігтів у домашніх тварин під час регулярного догляду. Використовуються для акуратного вкорочення кігтів у собак, котів та інших домашніх тварин у побутових умовах або під час базових процедур грумінгу.</span></article> <article data-scroll-anchor="true" data-testid="conversation-turn-20" data-turn="assistant" data-turn-id="request-69b34cbf-a33c-8331-8c2a-2d7e0ab1d4ae-6" dir="auto" tabindex="-1"> <p data-end="493" data-start="290"><span style="font-size:18px;"><strong data-end="306" data-start="290">Призначення:</strong></span><span style="font-size:14px;"> підходять для підтримання оптимальної довжини кігтів, запобігання їх надмірному відростанню та дискомфорту під час руху тварини. Застосовуються у процесі регулярного догляду за лапами.</span></p> <p data-end="739" data-start="495"><span style="font-size:18px;"><strong data-end="511" data-start="495">Конструкція:</strong> </span><span style="font-size:14px;">інструмент оснащений ріжучим механізмом кусачкового типу, що забезпечує контрольоване стискання лез під час обрізання кігтя. Форма ріжучої частини дозволяє точно позиціонувати інструмент і виконувати обрізання окремих кігтів.</span></p> <p data-end="950" data-start="741"><span style="font-size:18px;"><strong data-end="755" data-start="741">Матеріали:</strong></span><span style="font-size:14px;"> леза виготовлені зі сталі, стійкої до регулярного використання та механічних навантажень. Руків&rsquo;я адаптовані для стабільного утримання інструмента та контрольованого натискання під час роботи.</span></p> <p data-end="1115" data-is-last-node="" data-is-only-node="" data-start="952"><span style="font-size:18px;"><strong data-end="968" data-start="952">Особливості:</strong></span><span style="font-size:14px;"> інструмент призначений для систематичного догляду за домашніми тваринами та використовується як частина базового набору інструментів для грумінгу.</span></p> </article> | AE11: Кусачки для кігтів тварин Fiskars— ручний інструмент для підстригання кігтів у домашніх тварин під час регулярного догляду. Використовуються для акуратного вкорочення кігтів у собак, котів та інших домашніх тварин у побутових умовах або під час базових процедур грумінгу. | AH11: 0 | AI11: 2026-03-15 23:31:05 | AN11: Нет | AO11: 8214200000 | AP11: 0 | AQ11: Выкл | AR11: Выкл | AU11: 0046561816476 | AW11: Нет | AX11: Нет
A12: 2009132 | B12: 2009132 | C12: 2009132 | D12: Кусачки великі для кігтів тварин Fiskars , 2/6, 19L (2009132) | E12: Кусачки великі для кігтів тварин Fiskars , 2/6, 19L (2009132) | F12: Fiskars | G12: FISKARS/ Аксесуари для тварин | H12: 999.00 | I12: 0.00 | J12: UAH | K12: Да | L12: =VLOOKUP(C12,Sheet1!$C:$L,10,0) -> China | M12: Немає в наявності | O12: https://fiskars-gratis.com.ua/content/images/8/kusachky-velyki-dlia-kihtiv-tvaryn-fiskars-2-6-19l-1816483-21980176405223_+61b33ae7cd.jpg; https://fiskars-gratis.com.ua/content/images/8/kusachky-velyki-dlia-kihtiv-tvaryn-fiskars-2-6-19l-1816483-11302373923839_+51e6451da7.jpg | R12: kusachky-velyki-dlia-kihtiv-tvaryn-fiskars-2-6-19l-1816483 | S12: https://fiskars-gratis.com.ua/kusachky-velyki-dlia-kihtiv-tvaryn-fiskars-2-6-19l-1816483/ | T12: 2026-03-15 23:30:54 | X12: Кусачки великі для кігтів тварин Fiskars , 2/6, 19L | AA12: 0 | AB12: 0 | AC12: 0 | AD12: <article data-scroll-anchor="false" data-testid="conversation-turn-17" data-turn="user" data-turn-id="3f36e1f7-214d-4254-b13f-8799e9026099" dir="auto" tabindex="-1">&nbsp;</article> <article data-scroll-anchor="true" data-testid="conversation-turn-18" data-turn="assistant" data-turn-id="request-69b34cbf-a33c-8331-8c2a-2d7e0ab1d4ae-5" dir="auto" tabindex="-1"> <p data-end="295" data-start="0"><span style="font-size:18px;"><strong data-end="54" data-start="0">Кусачки великі для кігтів тварин Fiskars (2009132)</strong> </span><span style="font-size:14px;">&mdash; ручний інструмент для підстригання кігтів у домашніх тварин під час регулярного догляду. Використовуються для акуратного вкорочення кігтів у собак, котів та інших домашніх тварин у побутових умовах або під час базових процедур грумінгу.</span></p> <p data-end="523" data-start="297"><span style="font-size:18px;"><strong data-end="313" data-start="297">Призначення:</strong></span><span style="font-size:14px;"> підходять для підстригання відрослих кігтів, підтримання їх оптимальної довжини та запобігання надмірному стиранню або деформації під час руху тварини. Застосовуються у процесі регулярного догляду за лапами.</span></p> <p data-end="746" data-start="525"><span style="font-size:18px;"><strong data-end="541" data-start="525">Конструкція:</strong></span><span style="font-size:14px;"> інструмент оснащений ріжучим механізмом кусачкового типу, що забезпечує контрольоване стискання лез під час обрізання кігтя. Форма ріжучої частини дозволяє точно позиціонувати інструмент під час роботи.</span></p> <p data-end="931" data-start="748"><span style="font-size:18px;"><strong data-end="762" data-start="748">Матеріали:</strong> </span><span style="font-size:14px;">леза виготовлені зі сталі, стійкої до регулярного використання. Руків&rsquo;я адаптовані для стабільного утримання інструмента та контрольованого зусилля під час обрізання.</span></p> <p data-end="1094" data-is-last-node="" data-is-only-node="" data-start="933"><span style="font-size:18px;"><strong data-end="949" data-start="933">Особливості:</strong></span><span style="font-size:14px;"> інструмент призначений для систематичного догляду за домашніми тваринами та використовується як частина базового набору аксесуарів для грумінгу.</span></p> </article> | AE12: Кусачки великі для кігтів тварин Fiskars— ручний інструмент для підстригання кігтів у домашніх тварин під час регулярного догляду. Використовуються для акуратного вкорочення кігтів у собак, котів та інших домашніх тварин у побутових умовах або під час базових процедур грумінгу. | AH12: 0 | AI12: 2026-03-15 23:30:40 | AN12: Нет | AO12: 8214200000 | AP12: 0 | AQ12: Выкл | AR12: Выкл | AU12: 0046561816483 | AW12: Нет | AX12: Нет
A13: 1019354 | B13: 1019354 | C13: 1019354 | D13: Скребок автомобільний Fiskars Solid (1019354) | E13: Скребок автомобільний Fiskars Solid (1019354) | F13: Fiskars | G13: FISKARS/Автоаксесуари Fiskars/Щітки та скрібки для авто | H13: 319.00 | I13: 0.00 | J13: UAH | K13: Да | L13: =VLOOKUP(C13,Sheet1!$C:$L,10,0) -> China | M13: В наявності | N13: FISKARS/Автоаксесуари Fiskars | O13: https://fiskars-gratis.com.ua/content/images/31/skrebok-avtomobilnyi-fiskars-solid-1019354-46861657243390_+d1c2ae8995.jpg; https://fiskars-gratis.com.ua/content/images/31/skrebok-avtomobilnyi-fiskars-solid-1019354-82231664622799_+61bc64ffe5.jpg; https://fiskars-gratis.com.ua/content/images/31/skrebok-avtomobilnyi-fiskars-solid-1019354-67176702943325_+7b3f0ff99f.jpg; https://fiskars-gratis.com.ua/content/images/31/skrebok-avtomobilnyi-fiskars-solid-1019354-16081562994669_+d6a00c0495.jpg | R13: skrebok-avtomobilnyi-fiskars-solid-1019354 | S13: https://fiskars-gratis.com.ua/skrebok-avtomobilnyi-fiskars-solid-1019354/ | T13: 2026-02-22 01:06:29 | X13: Скребок автомобільний Fiskars Solid | AA13: 0 | AB13: 0 | AC13: 24 | AD13: <p data-end="311" data-start="0"><span style="font-size:18px;"><strong data-end="49" data-start="0">Скребок автомобільний Fiskars Solid (1019354)</strong> </span><span style="font-size:14px;">&mdash; ручний зимовий інструмент для очищення автомобільних стекол і зовнішніх поверхонь від льоду, намерзлого снігу та криги. Використовується для зняття льоду з лобового, бокових і заднього скла, а також дзеркал та інших зовнішніх деталей автомобіля перед виїздом.</span></p> <p data-end="543" data-start="313"><span style="font-size:18px;"><strong data-end="329" data-start="313">Призначення:</strong></span><span style="font-size:14px;"> підходить для очищення автомобільних вікон і дзеркал у зимовий період, коли на поверхні утворюється льодовий наліт; застосовується для швидкого видалення льоду без застосування аерозолів чи інших хімічних засобів.</span></p> <p data-end="786" data-start="545"><span style="font-size:18px;"><strong data-end="561" data-start="545">Конструкція:</strong></span><span style="font-size:14px;"> робоча частина оснащена твердою кромкою або щіточним елементом для зчищення льоду зі скла. Ергономічна рукоять забезпечує надійний захват та контроль під час чищення, зменшуючи навантаження на руку і підвищуючи ефективність.</span></p> <p data-end="1008" data-start="788"><span style="font-size:18px;"><strong data-end="802" data-start="788">Матеріали:</strong> </span><span style="font-size:14px;">скребок виготовлений із міцного пластику або композитного матеріалу, стійкого до низьких температур і механічних навантажень. Рукоять адаптована для комфортного використання в холодних умовах без ковзання.</span></p> <p data-end="1206" data-start="1010"><span style="font-size:18px;"><strong data-end="1026" data-start="1010">Особливості:</strong></span><span style="font-size:14px;"> інструмент належить до серії Solid бренду Fiskars та призначений для регулярного очищення автомобільних поверхонь від льоду й снігу в зимовий період.</span></p> | AE13: Скребок автомобільний Fiskars Solid — ручний зимовий інструмент для очищення автомобільних стекол і зовнішніх поверхонь від льоду, намерзлого снігу та криги. | AH13: 0 | AI13: 2026-02-22 23:14:10 | AM13: Новий | AN13: Нет | AO13: 9603909900 | AP13: 0 | AQ13: Выкл | AR13: Выкл | AU13: 6411501430632 | AW13: Нет | AX13: Нет
A14: 1078497 | B14: 1078497 | C14: 1078497 | D14: Скребок для льоду Fiskars Solid (1078497) | E14: Скребок для льоду Fiskars Solid (1078497) | F14: Fiskars | G14: FISKARS/Автоаксесуари Fiskars/Щітки та скрібки для авто | H14: 729.00 | I14: 0.00 | J14: UAH | K14: Да | L14: =VLOOKUP(C14,Sheet1!$C:$L,10,0) -> China | M14: В наявності | N14: FISKARS/Автоаксесуари Fiskars | O14: https://fiskars-gratis.com.ua/content/images/30/skrebok-dlia-lodu-fiskars-solid-1078497-69704877253493_+68d07e6800.jpg; https://fiskars-gratis.com.ua/content/images/30/skrebok-dlia-lodu-fiskars-solid-1078497-58463316290665_+765853dd9e.jpg; https://fiskars-gratis.com.ua/content/images/30/skrebok-dlia-lodu-fiskars-solid-1078497-79477715670594_+1c3f69b42b.jpg; https://fiskars-gratis.com.ua/content/images/30/skrebok-dlia-lodu-fiskars-solid-1078497-21271282967417_+1277b3a838.jpg | R14: skrebok-dlia-lodu-fiskars-solid-1078497 | S14: https://fiskars-gratis.com.ua/skrebok-dlia-lodu-fiskars-solid-1078497/ | T14: 2026-02-22 01:06:28 | X14: Скребок для льоду Fiskars Solid | AA14: 0 | AB14: 0 | AC14: 24 | AD14: <p data-end="304" data-start="0"><span style="font-size:18px;"><strong data-end="45" data-start="0">Скребок для льоду Fiskars Solid (1078497)</strong></span><span style="font-size:14px;"> &mdash; ручний зимовий інструмент для видалення льоду та намерзлого снігу з різних поверхонь. Використовується для очищення скла автомобіля, стекол, дзеркал, вітрових стекол, а також твердих горизонтальних поверхонь, де утворюється тонкий або середній шар льоду.</span></p> <p data-end="514" data-start="306"><span style="font-size:18px;"><strong data-end="322" data-start="306">Призначення:</strong></span><span style="font-size:14px;"> підходить для очищення автомобільних стекол і дзеркал, дверних прорізів, терас, сходинок і інших відкритих поверхонь, де потрібно ефективно усунути льодові утворення без пошкодження основи.</span></p> <p data-end="754" data-start="516"><span style="font-size:18px;"><strong data-end="532" data-start="516">Конструкція:</strong> </span><span style="font-size:14px;">оснащений твердою ріжучою кромкою, що дозволяє зчищати лід із поверхні шляхом легкого натискання та переміщення вздовж. Ергономічна рукоять адаптована для комфортного захвату й контролю під час роботи в холодних умовах.</span></p> <p data-end="1006" data-start="756"><span style="font-size:18px;"><strong data-end="770" data-start="756">Матеріали:</strong></span><span style="font-size:14px;"> робочий елемент виготовлений із міцного пластику або композитного матеріалу, стійкого до механічного навантаження й впливу низьких температур. Рукоять виконана з міцного матеріалу, що забезпечує надійний захват під час чищення льоду.</span></p> <p data-end="1201" data-start="1008"><span style="font-size:18px;"><strong data-end="1024" data-start="1008">Особливості:</strong></span><span style="font-size:14px;"> скребок належить до серії Solid бренду Fiskars та призначений для ефективного видалення льоду з поверхонь без застосування важких фізичних зусиль.</span></p> | AE14: Скребок для льоду Fiskars Solid — ручний зимовий інструмент для видалення льоду та намерзлого снігу з різних поверхонь. | AH14: 0 | AI14: 2026-02-22 23:13:01 | AM14: Новий | AN14: Нет | AO14: 3926909790 | AP14: 0 | AQ14: Выкл | AR14: Выкл | AU14: 6411501410573 | AW14: Нет | AX14: Нет
A15: 1082341 | B15: 1082341 | C15: 1082341 | D15: Акумулятор Fiskars 12V-4Ah (1082341) | E15: Акумулятор Fiskars 12V-4Ah (1082341) | F15: Fiskars | G15: FISKARS/Акумуляторний інструмент | H15: 4199.00 | I15: 5999.00 | J15: UAH | K15: Да | L15: =VLOOKUP(C15,Sheet1!$C:$L,10,0) -> China | M15: Немає в наявності | O15: https://fiskars-gratis.com.ua/content/images/15/akumuliator-fiskars-12v-4ah-1082341-65541202309766_+64755191c4.jpg | R15: akumuliator-fiskars-12v-4ah-1082341 | S15: https://fiskars-gratis.com.ua/akumuliator-fiskars-12v-4ah-1082341/ | T15: 2026-03-17 07:43:56 | X15: Акумулятор Fiskars 12V-4Ah | AA15: 0 | AB15: 0 | AC15: 0 | AD15: <p data-end="296" data-start="0"><span style="font-size:18px;"><strong data-end="40" data-start="0">Акумулятор Fiskars 12V-4Ah (1082341)</strong> </span><span style="font-size:14px;">&mdash; змінний акумуляторний блок для живлення садових електроінструментів акумуляторної лінійки Fiskars. Використовується як джерело енергії для бездротових інструментів під час виконання садових робіт на присадибних ділянках, у садах і господарських зонах.</span></p> <p data-end="557" data-start="298"><span style="font-size:18px;"><strong data-end="314" data-start="298">Призначення:</strong></span><span style="font-size:14px;"> підходить для забезпечення автономної роботи сумісних акумуляторних інструментів Fiskars, зокрема обладнання для обрізання рослин та інших робіт із догляду за садом. Дозволяє підтримувати роботу інструмента без підключення до електромережі.</span></p> <p data-end="803" data-start="559"><span style="font-size:18px;"><strong data-end="575" data-start="559">Конструкція:</strong></span><span style="font-size:14px;"> акумулятор виконаний у вигляді компактного змінного блока, який встановлюється у відповідний відсік інструмента та фіксується під час роботи. Форм-фактор забезпечує швидке встановлення та зняття під час заміни або заряджання.</span></p> <p data-end="943" data-start="805"><span style="font-size:18px;"><strong data-end="819" data-start="805">Матеріали:</strong></span><span style="font-size:14px;"> корпус виготовлений із ударостійкого технічного пластику, що захищає внутрішні елементи акумулятора під час експлуатації.</span></p> <p data-end="1113" data-is-last-node="" data-is-only-node="" data-start="945"><span style="font-size:18px;"><strong data-end="961" data-start="945">Особливості:</strong></span><span style="font-size:14px;"> акумулятор має робочу напругу 12 В і ємність 4 Ah. Призначений для багаторазового використання з сумісними акумуляторними інструментами бренду Fiskars.</span></p> | AE15: Акумулятор Fiskars 12V-4Ah — змінний акумуляторний блок для живлення садових електроінструментів акумуляторної лінійки Fiskars. Використовується як джерело енергії для бездротових інструментів під час виконання садових робіт на присадибних ділянках, у садах і господарських зонах. | AH15: 24 | AI15: 2026-03-17 07:43:29 | AN15: Нет | AO15: 8507 20 90 00 | AP15: 0 | AQ15: Выкл | AR15: Выкл | AU15: 46561816599 | AW15: Нет | AX15: Нет
A16: 1082298 | B16: 1082298 | C16: 1082298 | D16: Секатор акумуляторний Fiskars ePruner L, Bypass, Tool-Only без АКБ (1082298) | E16: Секатор акумуляторний Fiskars ePruner L, Bypass, Tool-Only без АКБ (1082298) | F16: Fiskars | G16: FISKARS/Акумуляторний інструмент | H16: 9999.00 | I16: 14999.00 | J16: UAH | K16: Да | L16: =VLOOKUP(C16,Sheet1!$C:$L,10,0) -> China | M16: Немає в наявності | O16: https://fiskars-gratis.com.ua/content/images/16/sekator-akumuliatornyi-fiskars-epruner-l-bypass-tool-only-bez-akb-1082298-43321917548533_+1b48282937.jpg; https://fiskars-gratis.com.ua/content/images/16/sekator-akumuliatornyi-fiskars-epruner-l-bypass-tool-only-bez-akb-1082298-25520542414971_+a5825b55f9.jpg | R16: sekator-akumuliatornyi-fiskars-epruner-l-bypass-tool-only-bez-akb-1082298 | S16: https://fiskars-gratis.com.ua/sekator-akumuliatornyi-fiskars-epruner-l-bypass-tool-only-bez-akb-1082298/ | T16: 2026-03-17 07:46:40 | X16: Секатор акумуляторний Fiskars ePruner L, Bypass, Tool-Only без АКБ | AA16: 0 | AB16: 0 | AC16: 0 | AD16: <p data-end="307" data-start="0"><span style="font-size:18px;"><strong data-end="80" data-start="0">Секатор акумуляторний Fiskars ePruner L, Bypass, Tool-Only без АКБ (1082298)</strong> </span><span style="font-size:14px;">&mdash; електричний ручний інструмент для обрізання гілок і догляду за деревами, кущами та декоративними рослинами у саду. Використовується для чистого зрізу живих пагонів під час формувального, санітарного та сезонного обрізання.</span></p> <p data-end="505" data-start="309"><span style="font-size:18px;"><strong data-end="325" data-start="309">Призначення:</strong></span><span style="font-size:14px;"> підходить для обрізання молодих і напівтвердих гілок, догляду за плодовими деревами, ягідними кущами, виноградом та декоративними насадженнями на присадибних і садових ділянках.</span></p> <p data-end="769" data-start="507"><span style="font-size:18px;"><strong data-end="523" data-start="507">Конструкція:</strong> </span><span style="font-size:14px;">ріжучий механізм типу bypass працює за принципом перехресного руху лез, що забезпечує точний зріз без значного пошкодження рослинних тканин. Електропривід автоматизує процес стискання лез і зменшує фізичне навантаження під час тривалої роботи.</span></p> <p data-end="960" data-start="771"><span style="font-size:18px;"><strong data-end="785" data-start="771">Матеріали:</strong></span><span style="font-size:14px;"> ріжучі леза виготовлені зі сталі, розрахованої на регулярне використання при обрізанні рослин. Корпус інструмента адаптований для ручної роботи та контролю під час різання.</span></p> <p data-end="1206" data-is-last-node="" data-is-only-node="" data-start="962"><span style="font-size:18px;"><strong data-end="978" data-start="962">Особливості:</strong> </span><span style="font-size:14px;">модель постачається у комплектації Tool-Only без акумулятора та зарядного пристрою і належить до акумуляторної садової лінійки бренду Fiskars. Призначена для систематичного використання під час догляду за садовими насадженнями.</span></p> | AE16: Секатор акумуляторний Fiskars ePruner L, Bypass, Tool-Only без АКБ — електричний ручний інструмент для обрізання гілок і догляду за деревами, кущами та декоративними рослинами у саду. Використовується для чистого зрізу живих пагонів під час формувального, санітарного та сезонного обрізання. | AH16: 24 | AI16: 2026-03-17 07:49:47 | AM16: Новий | AN16: Нет | AO16: 8467 29 00 00 | AP16: 0 | AQ16: Выкл | AR16: Выкл | AU16: 46561816568 | AW16: Нет | AX16: Нет
A17: 1082297 | B17: 1082297 | C17: 1082297 | D17: Секатор акумуляторний Fiskars ePruner M Bypassі з вбудованим акумулятором 8В 4 4Ah (1082297) | E17: Секатор акумуляторний Fiskars ePruner M Bypassі з вбудованим акумулятором 8В 4 4Ah (1082297) | F17: Fiskars | G17: FISKARS/Акумуляторний інструмент | H17: 9999.00 | I17: 14999.00 | J17: UAH | K17: Да | L17: =VLOOKUP(C17,Sheet1!$C:$L,10,0) -> China | M17: Немає в наявності | O17: https://fiskars-gratis.com.ua/content/images/17/sekator-akumuliatornyi-fiskars-epruner-m-bypassi-z-vbudovanym-akumuliatorom-8v-4-4ah-1082297-33665381691237_+f8640934ac.jpg; https://fiskars-gratis.com.ua/content/images/17/sekator-akumuliatornyi-fiskars-epruner-m-bypassi-z-vbudovanym-akumuliatorom-8v-4-4ah-1082297-71495293473480_+29081396f5.jpg; https://fiskars-gratis.com.ua/content/images/17/sekator-akumuliatornyi-fiskars-epruner-m-bypassi-z-vbudovanym-akumuliatorom-8v-4-4ah-1082297-84160697752622_+9ebb1b0aef.jpg | R17: sekator-akumuliatornyi-fiskars-epruner-m-bypassi-z-vbudovanym-akumuliatorom-8v-4-4ah-1082297 | S17: https://fiskars-gratis.com.ua/sekator-akumuliatornyi-fiskars-epruner-m-bypassi-z-vbudovanym-akumuliatorom-8v-4-4ah-1082297/ | T17: 2026-03-17 07:46:41 | X17: Секатор акумуляторний Fiskars ePruner M Bypass із вбудованим акумулятором 8В 4,4Ah | AA17: 0 | AB17: 0 | AC17: 0 | AD17: <p data-end="336" data-start="0"><span style="font-size:18px;"><strong data-end="96" data-start="0">Секатор акумуляторний Fiskars ePruner M Bypass із вбудованим акумулятором 8В 4,4Ah (1082297)</strong></span><span style="font-size:14px;"> &mdash; електричний ручний інструмент для обрізання гілок під час догляду за деревами, кущами та декоративними рослинами. Використовується для формувального та санітарного обрізання живих пагонів у садах, розсадниках і на присадибних ділянках.</span></p> <p data-end="596" data-start="338"><span style="font-size:18px;"><strong data-end="354" data-start="338">Призначення:</strong> </span><span style="font-size:14px;">підходить для обрізання молодих і напівтвердих гілок, догляду за плодовими деревами, ягідними кущами, виноградом та декоративними насадженнями. Дає змогу виконувати регулярні роботи з формування крони та підтримання здорового росту рослин.</span></p> <p data-end="893" data-start="598"><span style="font-size:18px;"><strong data-end="614" data-start="598">Конструкція:</strong></span><span style="font-size:14px;"> ріжучий механізм типу bypass працює за принципом перехресного руху лез, що забезпечує чистий зріз без значного пошкодження рослинних тканин. Електропривід автоматизує рух лез і зменшує фізичне навантаження під час роботи. Компактний корпус розрахований на роботу однією рукою.</span></p> <p data-end="1070" data-start="895"><span style="font-size:18px;"><strong data-end="909" data-start="895">Матеріали:</strong></span><span style="font-size:14px;"> леза виготовлені зі сталі, стійкої до регулярного використання при обрізанні рослин. Руків&rsquo;я адаптоване для контрольованого різання та тривалої ручної роботи.</span></p> <p data-end="1337" data-is-last-node="" data-is-only-node="" data-start="1072"><span style="font-size:18px;"><strong data-end="1088" data-start="1072">Особливості:</strong></span><span style="font-size:14px;"> модель оснащена вбудованим акумулятором 8 В ємністю 4,4 Ah, що забезпечує автономну роботу без зовнішнього джерела живлення. Інструмент належить до акумуляторної садової лінійки бренду Fiskars та призначений для систематичного догляду за рослинами.</span></p> | AE17: Секатор акумуляторний Fiskars ePruner M Bypass із вбудованим акумулятором 8В 4,4Ah — електричний ручний інструмент для обрізання гілок під час догляду за деревами, кущами та декоративними рослинами. Використовується для формувального та санітарного обрізання живих пагонів у садах, розсадниках і на присадибних ділянках. | AH17: 24 | AI17: 2026-03-17 07:50:16 | AM17: Новий | AN17: Нет | AO17: 8467 29 00 00 | AP17: 0 | AQ17: Выкл | AR17: Выкл | AU17: 46561816551 | AW17: Нет | AX17: Нет
A18: 1052240 | B18: 1052240 | C18: 1052240 | D18: Каструля Fiskars Hard Face Steel 3,5 л (1052240) | E18: Каструля Fiskars Hard Face Steel 3,5 л (1052240) | F18: Fiskars | G18: FISKARS/Посуд та кухонний інвентар Fiskars/Каструлі | H18: 3999.00 | I18: 5475.00 | J18: UAH | K18: Да | L18: =VLOOKUP(C18,Sheet1!$C:$L,10,0) -> Finland | M18: В наявності | N18: FISKARS/Посуд та кухонний інвентар Fiskars/Кухонне приладдя | O18: https://fiskars-gratis.com.ua/content/images/16/kastrulia-fiskars-hard-face-steel-35-l-1052240-48318519716309_+ab392840bb.jpg; https://fiskars-gratis.com.ua/content/images/16/kastrulia-fiskars-hard-face-steel-35-l-1052240-41910918198591_+9b7aeda45a.jpg; https://fiskars-gratis.com.ua/content/images/16/kastrulia-fiskars-hard-face-steel-35-l-1052240-91388840221464_+7df24964f1.jpg; https://fiskars-gratis.com.ua/content/images/16/kastrulia-fiskars-hard-face-steel-35-l-1052240-54369771624979_+9691b89190.jpg | R18: kastrulia-fiskars-hard-face-steel-35-l-1052240 | S18: https://fiskars-gratis.com.ua/kastrulia-fiskars-hard-face-steel-35-l-1052240/ | T18: 2026-02-22 16:32:03 | X18: Каструля Fiskars Hard Face Steel 3,5 л | AA18: 0 | AB18: 0 | AC18: 34 | AD18: <p><span style="font-size:18px;"><strong>Каструля Fiskars Hard Face Steel 3,5 л (1052240)</strong> </span><span style="font-size:14px;">&mdash; кухонний посуд для приготування рідких і напіврідких страв на плиті. Використовується для варіння супів, бульйонів, соусів, тушкування овочів, м&rsquo;яса та інших інгредієнтів, що потребують рівномірного нагріву і достатнього об&rsquo;єму.</span></p> <p data-end="503" data-start="287"><span style="font-size:18px;"><strong data-end="303" data-start="287">Призначення:</strong> </span><span style="font-size:14px;">підходить для повсякденного приготування страв великого і середнього обсягу у домашній кухні, де важливі стабільний розподіл тепла, контроль температури і можливість тривалого томління під кришкою.</span></p> <p data-end="808" data-start="505"><span style="font-size:18px;"><strong data-end="521" data-start="505">Конструкція:</strong> </span><span style="font-size:14px;">об&rsquo;єм 3,5 л і висока циліндрична форма забезпечують достатній простір для рідких страв і тушкованих сумішей. Кришка утримує пар і вологу під час приготування, сприяючи збереженню смакових якостей інгредієнтів. Руків&rsquo;я адаптоване для надійного захвату при перемішуванні та перенесенні.</span></p> <p data-end="1103" data-start="810"><span style="font-size:18px;"><strong data-end="824" data-start="810">Матеріали:</strong> </span><span style="font-size:14px;">корпус і робоча частина виготовлені зі сталі з твердим покриттям Hard Face Steel, що підвищує стійкість до подряпин і деформацій при регулярному використанні. Покриття сприяє рівномірному розподіленню тепла по поверхні. Руків&rsquo;я забезпечує контроль і комфорт під час готування.</span></p> <p data-end="1340" data-is-last-node="" data-is-only-node="" data-start="1105"><span style="font-size:18px;"><strong data-end="1121" data-start="1105">Особливості:</strong> </span><span style="font-size:14px;">каструля належить до серії Hard Face Steel бренду Fiskars та призначена для систематичного використання у процесі приготування страв, що потребують значного об&rsquo;єму і рівномірного прогріву.</span></p> | AE18: Каструля Fiskars Hard Face Steel 3,5 л — кухонний посуд для приготування рідких і напіврідких страв на плиті. Використовується для варіння супів, бульйонів, соусів, тушкування овочів, м’яса та інших інгредієнтів, що потребують рівномірного нагріву і достатнього об’єму. | AH18: 0 | AI18: 2026-02-22 23:01:38 | AL18: Facebook Feed; Google Feed for Merchant Center | AM18: Новий | AN18: Нет | AO18: 7323930090 | AP18: 0 | AQ18: Выкл | AR18: Выкл | AU18: 6411501702579 | AW18: Нет | AX18: Нет
